Workbook

Sheet TODOS
A1: LISTADO DE RIESGOS MÁS HABITUALES EN UN PROYECTO TIC
A2: COD. | B2: RIESGO | C2: PROBABILIDAD | D2: IMPACTO | E2: RIESGO
A3: A | B3: Elaboración de la Planificación | D3: Máximo | E3: =MAX(E4:E15) -> 0
A4: A.1. | B4: Las definiciones de la planificación, de los recursos y del producto han sido impuestas por el cliente o un directivo superior, y no están equilibradas. | E4: =+C4*D4 -> 0
A5: A.2. | B5: Planificación optimista, «mejor caso» (en lugar de realista, «caso esperado»). | E5: =+C5*D5 -> 0
A6: A.3. | B6: La planificación no incluye tareas necesarias. | E6: =+C6*D6 -> 0
A7: A.4. | B7: La planificación se ha basado en la utilización de personas específicas de un equipo, pero estas personas no están disponibles. | E7: =+C7*D7 -> 0
A8: A.5. | B8: No se puede construir un producto de tal envergadura en el tiempo asignado. | E8: =+C8*D8 -> 0
A9: A.6. | B9: El producto es más grande que el estimado (en líneas de código, en el número de puntos función, o en relación con el tamaño del proyecto anterior). | E9: =+C9*D9 -> 0
A10: A.7. | B10: El esfuerzo es mayor que el estimado (por líneas de código, número de puntos función, módulos, etc.). | E10: =+C10*D10 -> 0
A11: A.8. | B11: La reestimación debida a un retraso en la planificación es demasiado optimista o ignora la historia del proyecto. | E11: =+C11*D11 -> 0
A12: A.9. | B12: La presión excesiva en la planificación reduce la productividad. | E12: =+C12*D12 -> 0
A13: A.10. | B13: La fecha final ha cambiado sin ajustarse al ámbito del producto o a los recursos disponibles. | E13: =+C13*D13 -> 0
A14: A.11. | B14: Un retraso en una tarea produce retrasos en cascada en las tareas dependientes. | E14: =+C14*D14 -> 0
A15: A.12. | B15: Las áreas desconocidas del producto llevan más tiempo del esperado en el diseño y en la implementación. | E15: =+C15*D15 -> 0
A16: B | B16: Organización y Gestión | D16: Máximo | E16: =MAX(E17:E28) -> 0
A17: B.1. | B17: El proyecto carece de un promotor efectivo en los superiores. | E17: =+C17*D17 -> 0
A18: B.2. | B18: El proyecto languidece demasiado en el inicio difuso. | E18: =+C18*D18 -> 0
A19: B.3. | B19: Los despidos y las reducciones de la plantilla reducen la capacidad del equipo. | E19: =+C19*D19 -> 0
A20: B.4. | B20: Dirección o marketing insisten en tomar decisiones técnicas que alargan la planificación | E20: =+C20*D20 -> 0
A21: B.5. | B21: La estructura inadecuada de un equipo reduce la productividad. | E21: =+C21*D21 -> 0
A22: B.6. | B22: El ciclo de revisión/decisión de la directiva es más lento de lo esperado. | E22: =+C22*D22 -> 0
A23: B.7. | B23: El presupuesto varía el plan del proyecto. | E23: =+C23*D23 -> 0
A24: B.8. | B24: La dirección toma decisiones que reducen la motivación del equipo de desarrollo. | E24: =+C24*D24 -> 0
A25: B.9. | B25: Las tareas no técnicas encargadas a terceros necesitan más tiempo del esperado (aprobación del presupuesto, aprobación de la adquisición de material, revisiones legales, seguridad, etc.). | E25: =+C25*D25 -> 0
A26: B.10. | B26: La planificación es demasiado mala para ajustarse a la velocidad de desarrollo deseada. | E26: =+C26*D26 -> 0
A27: B.11. | B27: Los planes del proyecto se abandonan por la presión, llevando al caos y a un desarrollo ineficiente. | E27: =+C27*D27 -> 0
A28: B.12. | B28: La dirección pone más énfasis en las heroicidades que en informarse exactamente del estado, lo que reduce su habilidad para detectar y corregir problemas. | E28: =+C28*D28 -> 0
A29: C | B29: Ambiente/Infraestructura de Desarrollo | D29: Máximo | E29: =MAX(E30:E36) -> 0
A30: C.1. | B30: Los espacios no están disponibles en el momento necesario. | E30: =+C30*D30 -> 0
A31: C.2. | B31: Los espacios están disponibles pero no son adecuados (por ejemplo, falta de teléfonos, cableado de la red, mobiliario, material de oficina, etc.). | E31: =+C31*D31 -> 0
A32: C.3. | B32: Los espacios están sobreutilizados, son ruidosos o distraen. | E32: =+C32*D32 -> 0
A33: C.4. | B33: Las herramientas de desarrollo no están disponibles en el momento deseado. | E33: =+C33*D33 -> 0
A34: C.5. | B34: Las herramientas de desarrollo no funcionan como se esperaba; el personal de desarrollo necesita tiempo para resolverlo o adaptarse a las nuevas herramientas. | E34: =+C34*D34 -> 0
A35: C.6. | B35: Las herramientas de desarrollo no se han elegido en función de sus características técnicas, y no proporcionan las prestaciones previstas. | E35: =+C35*D35 -> 0
A36: C.7. | B36: La curva de aprendizaje para la nueva herramienta de desarrollo es más larga de lo esperado. | E36: =+C36*D36 -> 0
A37: D | B37: Usuarios Finales | D37: Máximo | E37: =MAX(E38:E41) -> 0
A38: D.1. | B38: Los usuarios finales insisten en nuevos requisitos. | E38: =+C38*D38 -> 0
A39: D.2. | B39: En el último momento, a los usuarios finales no les gusta el producto, por lo que hay que volver a diseñarlo y a construirlo. | E39: =+C39*D39 -> 0
A40: D.3. | B40: Los usuarios no han realizado la compra del material necesario para el proyecto y, por tanto, no tienen la infraestructura necesaria. | E40: =+C40*D40 -> 0
...

Sheet SELECCION
A1: SELECCIÓN DE RIESGOS MÁS CRITICOS POR CATEGORIA
A2: COD. | B2: RIESGO | C2: PROBABILIDAD | D2: IMPACTO | E2: V. RIESGO | F2: ACC. RECOMEN
A3: A | B3: Elaboración de la Planificación
E4: =+C4*D4 -> 0 | F4: =IF(E4=0,"",IF(E4>='NIVEL DE RIESGO'!$C$9,"MITIGACION",IF(E4>'NIVEL DE RIESGO'!$C$10,"CONTINGENCIA","")))
A5: B | B5: Organización y Gestión
E6: =+C6*D6 -> 0 | F6: =IF(E6=0,"",IF(E6>='NIVEL DE RIESGO'!$C$9,"MITIGACION",IF(E6>'NIVEL DE RIESGO'!$C$10,"CONTINGENCIA","")))
A7: C/D | B7: Ambiente/Infraestructura de Desarrollo - Usuarios Finales
E8: =+C8*D8 -> 0 | F8: =IF(E8=0,"",IF(E8>='NIVEL DE RIESGO'!$C$9,"MITIGACION",IF(E8>'NIVEL DE RIESGO'!$C$10,"CONTINGENCIA","")))
A9: E | B9: Cliente
E10: =+C10*D10 -> 0 | F10: =IF(E10=0,"",IF(E10>='NIVEL DE RIESGO'!$C$9,"MITIGACION",IF(E10>'NIVEL DE RIESGO'!$C$10,"CONTINGENCIA","")))
A11: F/G | B11: Personal Contratado - Requisitos
E12: =+C12*D12 -> 0 | F12: =IF(E12=0,"",IF(E12>='NIVEL DE RIESGO'!$C$9,"MITIGACION",IF(E12>'NIVEL DE RIESGO'!$C$10,"CONTINGENCIA","")))
A13: H/I | B13: Producto - Fuerzas Mayores
E14: =+C14*D14 -> 0 | F14: =IF(E14=0,"",IF(E14>='NIVEL DE RIESGO'!$C$9,"MITIGACION",IF(E14>'NIVEL DE RIESGO'!$C$10,"CONTINGENCIA","")))
A15: J | B15: Personal
E16: =+C16*D16 -> 0 | F16: =IF(E16=0,"",IF(E16>='NIVEL DE RIESGO'!$C$9,"MITIGACION",IF(E16>'NIVEL DE RIESGO'!$C$10,"CONTINGENCIA","")))
A17: K | B17: Diseño e Implementación
E18: =+C18*D18 -> 0 | F18: =IF(E18=0,"",IF(E18>='NIVEL DE RIESGO'!$C$9,"MITIGACION",IF(E18>'NIVEL DE RIESGO'!$C$10,"CONTINGENCIA","")))
A19: L | B19: Proceso
E20: =+C20*D20 -> 0 | F20: =IF(E20=0,"",IF(E20>='NIVEL DE RIESGO'!$C$9,"MITIGACION",IF(E20>'NIVEL DE RIESGO'!$C$10,"CONTINGENCIA","")))

Sheet MITIGACIÓN
A1: ACCIONES DE MITIGACION DE RIESGOS
A2: COD. | B2: RIESGO 1 | D2: PROBABILIDAD | E2: IMPACTO | F2: V. RIESGO
F3: =+D3*E3 -> 0
A4: MEDIDAS DE MITIGACIÓN | D4: NUEVA PROB. | E4: NUEVO IMPC. | F4: V. RIESGO
A5: 1 | F5: =+D5*E5 -> 0
A6: 2
A7: 3
A9: COD. | B9: RIESGO 2 | D9: PROBABILIDAD | E9: IMPACTO | F9: V. RIESGO
F10: =+D10*E10 -> 0
A11: MEDIDAS DE MITIGACIÓN | D11: NUEVA PROB. | E11: NUEVO IMPC. | F11: V. RIESGO
A12: 1 | F12: =+D12*E12 -> 0
A13: 2
A14: 3
A16: COD. | B16: RIESGO 3 | D16: PROBABILIDAD | E16: IMPACTO | F16: V. RIESGO
F17: =+D17*E17 -> 0
A18: MEDIDAS DE MITIGACIÓN | D18: NUEVA PROB. | E18: NUEVO IMPC. | F18: V. RIESGO
A19: 1 | F19: =+D19*E19 -> 0
A20: 2
A21: 3
A23: COD. | B23: RIESGO 4 | D23: PROBABILIDAD | E23: IMPACTO | F23: V. RIESGO
F24: =+D24*E24 -> 0
A25: MEDIDAS DE MITIGACIÓN | D25: NUEVA PROB. | E25: NUEVO IMPC. | F25: V. RIESGO
A26: 1 | F26: =+D26*E26 -> 0
A27: 2
A28: 3
A30: COD. | B30: RIESGO 5 | D30: PROBABILIDAD | E30: IMPACTO | F30: V. RIESGO
F31: =+D31*E31 -> 0
A32: MEDIDAS DE MITIGACIÓN | D32: NUEVA PROB. | E32: NUEVO IMPC. | F32: V. RIESGO
A33: 1 | F33: =+D33*E33 -> 0
A34: 2
A35: 3
A37: COD. | B37: RIESGO 6 | D37: PROBABILIDAD | E37: IMPACTO | F37: V. RIESGO
F38: =+D38*E38 -> 0
A39: MEDIDAS DE MITIGACIÓN | D39: NUEVA PROB. | E39: NUEVO IMPC. | F39: V. RIESGO
A40: 1 | F40: =+D40*E40 -> 0
A41: 2
A42: 3

Sheet CONTINGENCIA
A1: ACCIONES DE CONTINGENCIA DE RIESGOS
A2: COD. | B2: RIESGO 1 | D2: PROBABILIDAD | E2: IMPACTO | F2: V. RIESGO
F3: =+D3*E3 -> 0
A4: MEDIDAS DE CONTINGENCIA
A5: 1
A6: 2
A7: 3
A9: COD. | B9: RIESGO 2 | D9: PROBABILIDAD | E9: IMPACTO | F9: V. RIESGO
F10: =+D10*E10 -> 0
A11: MEDIDAS DE CONTINGENCIA
A12: 1
A13: 2
A14: 3
A16: COD. | B16: RIESGO 3 | D16: PROBABILIDAD | E16: IMPACTO | F16: V. RIESGO
F17: =+D17*E17 -> 0
A18: MEDIDAS DE CONTINGENCIA
A19: 1
A20: 2
A21: 3
A23: COD. | B23: RIESGO 4 | D23: PROBABILIDAD | E23: IMPACTO | F23: V. RIESGO
F24: =+D24*E24 -> 0
A25: MEDIDAS DE CONTINGENCIA
A26: 1
A27: 2
A28: 3
A30: COD. | B30: RIESGO 5 | D30: PROBABILIDAD | E30: IMPACTO | F30: V. RIESGO
F31: =+D31*E31 -> 0
A32: MEDIDAS DE CONTINGENCIA
A33: 1
A34: 2
A35: 3
A37: COD. | B37: RIESGO 6 | D37: PROBABILIDAD | E37: IMPACTO | F37: V. RIESGO
F38: =+D38*E38 -> 0
A39: MEDIDAS DE CONTINGENCIA
A40: 1
A41: 2
A42: 3

Sheet NIVEL DE RIESGO
B2: MAXIMO VALOR | C2: =MAX(SELECCION!E4,SELECCION!E6,SELECCION!E8,SELECCION!E10,SELECCION!E12,SELECCION!E14,SELECCION!E16,SELECCION!E18,SELECCION!E20) -> 0
B3: MINIMO VALOR | C3: =MIN(SELECCION!E4,SELECCION!E6,SELECCION!E8,SELECCION!E10,SELECCION!E12,SELECCION!E14,SELECCION!E16,SELECCION!E18,SELECCION!E20) -> 0
B4: PROMEDIO | C4: =AVERAGE(SELECCION!E4,SELECCION!E6,SELECCION!E8,SELECCION!E10,SELECCION!E12,SELECCION!E14,SELECCION!E16,SELECCION!E18,SELECCION!E20) -> 0
B6: DIFERENCIA SUP | C6: =+(C2-C4)/3 -> 0
B7: DIFERENCIA INF | C7: =+(C4-C3)/3 -> 0
B9: MITIGACIÓN | C9: =+C4+C6 -> 0
B10: CONTINGENCIA | C10: =+C4-C7 -> 0
