Workbook

Sheet OVERHEAD
A1: HOJA DE ESTIMACIÓN DEL OVERHEAD DE LA EMPRESA
B3: PORCENTAJE DE COSTES INDIRECTOS (OVERHEAD) | F3: =+F23/C23 -> 0.38795477
B5: GASTOS DIRECTOS | E5: GASTOS INDIRECTOS
B6: CONCEPTO | C6: IMPORTE ANUAL | E6: CONCEPTO | F6: IMPORTE ANUAL
B7: Jefe de proyecto | C7: 80000 | E7: Comercial | F7: 80000
B8: Analista | C8: 120000 | E8: Gerente | F8: 45000
B9: Técnico de sistemas | C9: 32000 | E9: Administrativo | F9: 51000
B10: Técnico de datos | C10: 32000 | E10: Personal de mantenimiento | F10: 18000
B11: Programador | C11: 337500 | E11: Alquiler locales | F11: 36000
B12: Diseñador gráfico | C12: 20000 | E12: Seguros responsabilidad | F12: 1500
B13: Supervisor | C13: 35000 | E13: Seguridad | F13: 6000
B14: Seguridad social | C14: =0.3*(SUM(C7:C13)) -> 196950 | E14: Limpieza | F14: 3600
E15: Luz | F15: 12000
E16: Agua | F16: 2000
E17: Papelería | F17: 4800
E18: Publicidad | F18: 5000
E19: Impuestos | F19: 8000
E20: Seguridad social | F20: =0.3*(SUM(F7:F10)) -> 58200
B23: TOTAL | C23: =SUM(C7:C22) -> 853450 | E23: TOTAL | F23: =SUM(F7:F22) -> 331100

Sheet ESTIMACION
A1: HOJA DE ESTIMACIÓN ECONÓMICA DE PROYECTO
A3: DATOS DEL PROYECTO
A5: TITULO: | C5: DESARROLLO DE UN PORTAL WEB | J5: REFERENCIA: | L5: DES-01-2022
A6: CLIENTE: | C6: MEDIOLADO | J6: RESPONSABLE: | L6: PABLO Y CAMILO
A8: FECHA INICIO: | C8: 44562 | J8: FECHA FIN: | L8: 44925
J10: PRECIO VENTA (SIN IVA): | M10: =+N94 -> 97148.99 | N10: Euros
J11: ESFUERZO (TRABAJO): | M11: =+G31 -> 3212 | N11: Horas
J12: MARGEN BENEFICIOS: | M12: =100*(N94-N81)/N81 -> 27.137575 | N12: %
A14: 1. ESTIMACIÓN DE COSTES Y GASTOS
B16: 1.A | C16: PERSONAL
J17: PORCENTAJE DE COSTES INDIRECTOS (OVERHEAD) | N17: =+OVERHEAD!F3 -> 0.38795477
J18: COTIZACIÓN SEGURIDAD SOCIAL | N18: 0.3
J19: PORCENTAJE CONTINGENCIAS PARA PERSONAL | N19: 0.05
C21: PERSONAL | G21: HORAS TR. | H21: Coste Bruto / Hora | J21: Coste SS / Hora | L21: Contingen./H | M21: Total / Hora | N21: COSTE FINAL
C22: Analista | G22: 710 | H22: =30000/1760 -> 17.045455 | J22: =+H22*$N$18 -> 5.1136364 | L22: =+(H22+J22)*$N$19 -> 1.1079545 | M22: =+L22+J22+H22 -> 23.267045 | N22: =+M22*G22 -> 16519.602
C23: Diseñador Gráfico Aplicativos | G23: 100 | H23: =20000/1760 -> 11.363636 | J23: =+H23*$N$18 -> 3.4090909 | L23: =+(H23+J23)*$N$19 -> 0.73863636 | M23: =+L23+J23+H23 -> 15.511364 | N23: =+M23*G23 -> 1551.1364
C24: Jefe de Proyecto | G24: 250 | H24: =40000/1760 -> 22.727273 | J24: =+H24*$N$18 -> 6.8181818 | L24: =+(H24+J24)*$N$19 -> 1.4772727 | M24: =+L24+J24+H24 -> 31.022727 | N24: =+M24*G24 -> 7755.6818
C25: Programador | G25: 1720 | H25: =22500/1760 -> 12.784091 | J25: =+H25*$N$18 -> 3.8352273 | L25: =+(H25+J25)*$N$19 -> 0.83096591 | M25: =+L25+J25+H25 -> 17.450284 | N25: =+M25*G25 -> 30014.489
C26: Supervisor calidad aplicativos | G26: 232 | H26: =35000/1760 -> 19.886364 | J26: =+H26*$N$18 -> 5.9659091 | L26: =+(H26+J26)*$N$19 -> 1.2926136 | M26: =+L26+J26+H26 -> 27.144886 | N26: =+M26*G26 -> 6297.6136
C27: Técnico de bases de datos | G27: 100 | H27: =32000/1760 -> 18.181818 | J27: =+H27*$N$18 -> 5.4545455 | L27: =+(H27+J27)*$N$19 -> 1.1818182 | M27: =+L27+J27+H27 -> 24.818182 | N27: =+M27*G27 -> 2481.8182
C28: Técnico de sistemas | G28: 100 | H28: =32000/1760 -> 18.181818 | J28: =+H28*$N$18 -> 5.4545455 | L28: =+(H28+J28)*$N$19 -> 1.1818182 | M28: =+L28+J28+H28 -> 24.818182 | N28: =+M28*G28 -> 2481.8182
C29: [Insertar más líneas aquí] | J29: =+H29*$N$18 -> 0 | L29: =+(H29+J29)*$N$19 -> 0 | M29: =+L29+J29+H29 -> 0 | N29: =+M29*G29 -> 0
C31: HORAS TOTALES | G31: =SUM(G22:G29) -> 3212 | K31: SUBTOTAL PERSONAL | N31: =SUM(N22:N29) -> 67102.159
B33: 1.B | C33: SUBCONTRATACIONES
I34: PORCENTAJE CONTINGENCIAS PARA SUBCONTRATACION
C36: EMPRESA | E36: DESCRIPCIÓN | I36: UNIDADES | J36: COSTE/U | L36: CONTING. | M36: TOTAL/U | N36: COSTE FINAL
C37: 3D Designs S.L | E37: 2150 | L37: =+J37*$N$34 -> 0 | M37: =+L37+J37 -> 0 | N37: =+I37*M37 -> 0
C38: Telefónica | E38: 49€ + 29/mes | L38: =+J38*$N$34 -> 0 | M38: =+L38+J38 -> 0 | N38: =+I38*M38 -> 0
L39: =+J39*$N$34 -> 0 | M39: =+L39+J39 -> 0 | N39: =+I39*M39 -> 0
C40: [Insertar más líneas aquí] | L40: =+J40*$N$34 -> 0 | M40: =+L40+J40 -> 0 | N40: =+I40*M40 -> 0
K42: SUBTOTAL SUBCONTRATACIÓN | N42: =SUM(N37:N40) -> 0
B44: 1.C | C44: EQUIPAMIENTO
J45: PORCENTAJE CONTINGENCIAS PARA EQUIPAMIENTO | N45: 0.02
C47: EQUIPO | E47: DESCRIPCIÓN (opcional) | I47: UNIDADES | J47: COSTE/U | L47: CONTING. | M47: TOTAL/U | N47: COSTE FINAL
C48: HW-SERV | E48: Tipo hardware, IBM | I48: 1 | J48: 4800 | L48: =+J48*$N$45 -> 96 | M48: =+L48+J48 -> 4896 | N48: =+M48*I48 -> 4896
C49: SW-SERV | E49: Tipo software, redhat | I49: 1 | J49: 250 | L49: =+J49*$N$45 -> 5 | M49: =+L49+J49 -> 255 | N49: =+M49*I49 -> 255
L50: =+J50*$N$45 -> 0 | M50: =+L50+J50 -> 0 | N50: =+M50*I50 -> 0
C51: [Insertar más líneas aquí] | L51: =+J51*$N$45 -> 0 | M51: =+L51+J51 -> 0 | N51: =+M51*I51 -> 0
K53: SUBTOTAL EQUIPAMIENTO | N53: =SUM(N48:N51) -> 5151
B55: 1.D | C55: AMORTIZACION HW/SW
...

Sheet PLAN FINANCIERO
A1: PLAN FINANCIERO DEL PROYECTO
A3: DATOS DEL PROYECTO
A5: TITULO: | C5: =IF(ESTIMACION!C5="","N/A",ESTIMACION!C5) -> DESARROLLO DE UN PORTAL WEB | I5: REFERENCIA: | K5: =IF(ESTIMACION!L5="","N/A",ESTIMACION!L5) -> DES-01-2022
A6: CLIENTE: | C6: =IF(ESTIMACION!C6="","N/A",ESTIMACION!C6) -> MEDIOLADO | I6: RESPONSABLE: | K6: =IF(ESTIMACION!L6="","N/A",ESTIMACION!L6) -> PABLO Y CAMILO
A8: FECHA INICIO: | D8: =IF(ESTIMACION!C8="","N/A",ESTIMACION!C8) -> 44562 | I8: FECHA FIN: | K8: =IF(ESTIMACION!L8="","N/A",ESTIMACION!L8) -> 44925
A10: FECHA INFORME : | D10: 44699 | I10: PRECIO VENTA (SIN IVA): | L10: =+ESTIMACION!M10 -> 97148.99 | N10: Euros
I11: ESFUERZO: | L11: =+ESTIMACION!M11 -> 3212 | N11: Horas
I12: MARGEN BENEFICIOS: | L12: =+ESTIMACION!M12 -> 27.137575 | N12: %
I14: TIPO INTERES ANUAL : | M14: 0.02
I15: COSTE DE OPORTUNIDAD ANUAL : | M15: 0.08
A17: 1. PROYECCION TEMPORAL DE COSTES Y GASTOS :
D19: DISTRIBUCION HORAS DE TRABAJO | Q19: TOTAL PREVISTO
A20: PERSONAL | D20: MES 1 | E20: MES 2 | F20: MES 3 | G20: MES 4 | H20: MES 5 | I20: MES 6 | J20: MES 7 | K20: MES 8 | L20: MES 9 | M20: MES 10 | N20: MES 11 | O20: MES 12 | P20: <INSER> | Q20: PLAN_F | R20: ESTIMADO
A21: =+ESTIMACION!C22 -> Analista | D21: =200*2/3 -> 133.33333 | E21: =200/3 + 250/5 -> 116.66667 | F21: =250*2/5 -> 100 | G21: =250*2/5 -> 100 | H21: =180/6 -> 30 | I21: =180/6 -> 30 | J21: =180/6 -> 30 | K21: =180/6 -> 30 | L21: =180/6 -> 30 | M21: =180/6 -> 30 | N21: =80/2 -> 40 | O21: =80/2 -> 40 | Q21: =SUM(D21:P21) -> 710 | R21: =+ESTIMACION!G22 -> 710
A22: =+ESTIMACION!C23 -> Diseñador Gráfico Aplicativos | D22: 0 | E22: 20 | F22: =100*2/5 -> 40 | G22: =100*2/5 -> 40 | H22: 0 | I22: 0 | J22: 0 | K22: 0 | L22: 0 | M22: 0 | N22: 0 | O22: 0 | Q22: =SUM(D22:P22) -> 100 | R22: =+ESTIMACION!G23 -> 100
A23: =+ESTIMACION!C24 -> Jefe de Proyecto | D23: =40*2/3 -> 26.666667 | E23: =40/3 + 40/5 -> 21.333333 | F23: =40*2/5 -> 16 | G23: =40*2/5 -> 16 | H23: =90/6 -> 15 | I23: =90/6 -> 15 | J23: =90/6 -> 15 | K23: =90/6 -> 15 | L23: =90/6 -> 15 | M23: =90/6 -> 15 | N23: =80/2 -> 40 | O23: =80/2 -> 40 | Q23: =SUM(D23:P23) -> 250 | R23: =+ESTIMACION!G24 -> 250
A24: =+ESTIMACION!C25 -> Programador | D24: 0 | E24: =100/5 -> 20 | F24: =100*2/5 -> 40 | G24: =100*2/5 -> 40 | H24: =1500/6 -> 250 | I24: =1500/6 -> 250 | J24: =1500/6 -> 250 | K24: =1500/6 -> 250 | L24: =1500/6 -> 250 | M24: =1500/6 -> 250 | N24: =120/2 -> 60 | O24: =120/2 -> 60 | Q24: =SUM(D24:P24) -> 1720 | R24: =+ESTIMACION!G25 -> 1720
A25: =+ESTIMACION!C26 -> Supervisor calidad aplicativos | D25: =20*2/3 -> 13.333333 | E25: =20/3 + 30/5 -> 12.666667 | F25: =30*2/5 -> 12 | G25: =30*2/5 -> 12 | H25: =102/6 -> 17 | I25: =102/6 -> 17 | J25: =102/6 -> 17 | K25: =102/6 -> 17 | L25: =102/6 -> 17 | M25: =102/6 -> 17 | N25: =80/2 -> 40 | O25: =80/2 -> 40 | Q25: =SUM(D25:P25) -> 232 | R25: =+ESTIMACION!G26 -> 232
A26: =+ESTIMACION!C27 -> Técnico de bases de datos | D26: =60*2/3 -> 40 | E26: =60/3 -> 20 | F26: 0 | G26: 0 | H26: 0 | I26: 0 | J26: 0 | K26: 0 | L26: 0 | M26: 0 | N26: =40/2 -> 20 | O26: =40/2 -> 20 | Q26: =SUM(D26:P26) -> 100 | R26: =+ESTIMACION!G27 -> 100
A27: =+ESTIMACION!C28 -> Técnico de sistemas | D27: 0 | E27: =60/5 -> 12 | F27: =60*2/5 -> 24 | G27: =60*2/5 -> 24 | H27: 0 | I27: 0 | J27: 0 | K27: 0 | L27: 0 | M27: 0 | N27: =40/2 -> 20 | O27: =40/2 -> 20 | Q27: =SUM(D27:P27) -> 100 | R27: =+ESTIMACION!G28 -> 100
A28: =+ESTIMACION!C29 -> [Insertar más líneas aquí] | Q28: =SUM(D28:P28) -> 0 | R28: =+ESTIMACION!G29 -> 0
A30: COSTE PERSONAL | D30: =SUMPRODUCT(ESTIMACION!$M$22:$M$29,'PLAN FINANCIERO'!D21:D28) -> 5284.2045 | E30: =SUMPRODUCT(ESTIMACION!$M$22:$M$29,'PLAN FINANCIERO'!E21:E28) -> 5173.5568 | F30: =SUMPRODUCT(ESTIMACION!$M$22:$M$29,'PLAN FINANCIERO'!F21:F28) -> 5062.9091 | G30: =SUMPRODUCT(ESTIMACION!$M$22:$M$29,'PLAN FINANCIERO'!G21:G28) -> 5062.9091 | H30: =SUMPRODUCT(ESTIMACION!$M$22:$M$29,'PLAN FINANCIERO'!H21:H28) -> 5987.3864 | I30: =SUMPRODUCT(ESTIMACION!$M$22:$M$29,'PLAN FINANCIERO'!I21:I28) -> 5987.3864 | J30: =SUMPRODUCT(ESTIMACION!$M$22:$M$29,'PLAN FINANCIERO'!J21:J28) -> 5987.3864 | K30: =SUMPRODUCT(ESTIMACION!$M$22:$M$29,'PLAN FINANCIERO'!K21:K28) -> 5987.3864 | ... P30: =SUMPRODUCT(ESTIMACION!$M$22:$M$29,'PLAN FINANCIERO'!P21:P28) -> 0 | Q30: =SUM(D30:P30) -> 67102.159 | R30: =+ESTIMACION!N31 -> 67102.159
D33: DISTRIBUCION HORAS DE TRABAJO | Q33: TOTAL PREVISTO
A34: =+ESTIMACION!C33 -> SUBCONTRATACIONES | D34: MES 1 | E34: MES 2 | F34: MES 3 | G34: MES 4 | H34: MES 5 | I34: MES 6 | J34: MES 7 | K34: MES 8 | L34: MES 9 | M34: MES 10 | N34: MES 11 | O34: MES 12 | P34: <INSER> | Q34: PLAN_F | R34: ESTIMADO
A35: =+ESTIMACION!C37 -> 3D Designs S.L | Q35: =SUM(D35:P35) -> 0 | R35: =+ESTIMACION!N37 -> 0
A36: =+ESTIMACION!C38 -> Telefónica | Q36: =SUM(D36:P36) -> 0 | R36: =+ESTIMACION!N38 -> 0
A37: =+ESTIMACION!C39 -> 0 | Q37: =SUM(D37:P37) -> 0 | R37: =+ESTIMACION!N39 -> 0
A38: =+ESTIMACION!C40 -> [Insertar más líneas aquí] | Q38: =SUM(D38:P38) -> 0 | R38: =+ESTIMACION!N40 -> 0
A40: COSTE SUBCONTRATACION | D40: =SUM(D35:D38) -> 0 | E40: =SUM(E35:E38) -> 0 | F40: =SUM(F35:F38) -> 0 | G40: =SUM(G35:G38) -> 0 | H40: =SUM(H35:H38) -> 0 | I40: =SUM(I35:I38) -> 0 | J40: =SUM(J35:J38) -> 0 | K40: =SUM(K35:K38) -> 0 | ... O40: =SUM(O35:O38) -> 0 | P40: =SUMPRODUCT(ESTIMACION!$M$22:$M$29,'PLAN FINANCIERO'!P30:P38) -> #VALUE! | Q40: =SUM(D40:P40) -> #VALUE! | R40: =SUM(R35:R38) -> 0
D43: DISTRIBUCION HORAS DE TRABAJO | Q43: TOTAL PREVISTO
A44: =+ESTIMACION!C44 -> EQUIPAMIENTO | D44: MES 1 | E44: MES 2 | F44: MES 3 | G44: MES 4 | H44: MES 5 | I44: MES 6 | J44: MES 7 | K44: MES 8 | L44: MES 9 | M44: MES 10 | N44: MES 11 | O44: MES 12 | P44: <INSER> | Q44: PLAN_F | R44: ESTIMADO
A45: =+ESTIMACION!C48 -> HW-SERV | D45: 0 | E45: 0 | F45: 0 | G45: 0 | H45: 0 | I45: 0 | J45: 0 | K45: 0 | L45: 0 | M45: =4800+ 0.02*4800 -> 4896 | N45: 0 | O45: 0 | Q45: =SUM(D45:P45) -> 4896 | R45: =+ESTIMACION!N48 -> 4896
A46: =+ESTIMACION!C49 -> SW-SERV | D46: 0 | E46: 0 | F46: 0 | G46: 0 | H46: 0 | I46: 0 | J46: 0 | K46: 0 | L46: 0 | M46: =250+0.02*250 -> 255 | N46: 0 | O46: 0 | Q46: =SUM(D46:P46) -> 255 | R46: =+ESTIMACION!N49 -> 255
A47: =+ESTIMACION!C50 -> 0 | Q47: =SUM(D47:P47) -> 0 | R47: =+ESTIMACION!N50 -> 0
A48: =+ESTIMACION!C51 -> [Insertar más líneas aquí] | Q48: =SUM(D48:P48) -> 0 | R48: =+ESTIMACION!N51 -> 0
A50: COSTE EQUIPAMIENTO | D50: =SUM(D45:D48) -> 0 | E50: =SUM(E45:E48) -> 0 | F50: =SUM(F45:F48) -> 0 | G50: =SUM(G45:G48) -> 0 | H50: =SUM(H45:H48) -> 0 | I50: =SUM(I45:I48) -> 0 | J50: =SUM(J45:J48) -> 0 | K50: =SUM(K45:K48) -> 0 | ... O50: =SUM(O45:O48) -> 0 | Q50: =SUM(D50:P50) -> 5151 | R50: =SUM(R45:R48) -> 5151
D53: DISTRIBUCION HORAS DE TRABAJO | Q53: TOTAL PREVISTO
A54: =+ESTIMACION!C69 -> OTROS GASTOS | D54: MES 1 | E54: MES 2 | F54: MES 3 | G54: MES 4 | H54: MES 5 | I54: MES 6 | J54: MES 7 | K54: MES 8 | L54: MES 9 | M54: MES 10 | N54: MES 11 | O54: MES 12 | P54: <INSER> | Q54: PLAN_F | R54: ESTIMADO
A55: =+ESTIMACION!C73 -> MATERIAL FUNGIBLE | D55: 110 | E55: 110 | F55: 110 | Q55: =SUM(D55:P55) -> 330 | R55: =+ESTIMACION!N73 -> 330
A56: =+ESTIMACION!C74 -> MATERIAL FUNGIBLE RESTO | G56: 55 | H56: 55 | I56: 55 | J56: 55 | K56: 55 | L56: 55 | M56: 55 | N56: 55 | O56: 55 | Q56: =SUM(D56:P56) -> 495 | R56: =+ESTIMACION!N74 -> 495
...

Sheet INDICADORES
A1: INDICADORES ECONÓMICOS Y FINANCIEROS DEL PROYECTO
A3: DATOS DEL PROYECTO
A5: TITULO: | C5: =IF(ESTIMACION!C5="","N/A",ESTIMACION!C5) -> DESARROLLO DE UN PORTAL WEB | I5: REFERENCIA: | K5: =IF(ESTIMACION!L5="","N/A",ESTIMACION!L5) -> DES-01-2022
A6: CLIENTE: | C6: =IF(ESTIMACION!C6="","N/A",ESTIMACION!C6) -> MEDIOLADO | I6: RESPONSABLE: | K6: =IF(ESTIMACION!L6="","N/A",ESTIMACION!L6) -> PABLO Y CAMILO
A8: FECHA INICIO: | D8: =IF(ESTIMACION!C8="","N/A",ESTIMACION!C8) -> 44562 | I8: FECHA FIN: | K8: =IF(ESTIMACION!L8="","N/A",ESTIMACION!L8) -> 44925
A10: FECHA INFORME : | D10: =IF('PLAN FINANCIERO'!D10:F10="","N/A",'PLAN FINANCIERO'!D10:F10) -> 44699 | I10: PRECIO VENTA (SIN IVA): | L10: =+ESTIMACION!M10 -> 97148.99 | N10: Euros
I11: ESFUERZO: | L11: =+ESTIMACION!M11 -> 3212 | N11: Horas
I12: MARGEN BENEFICIOS: | L12: =+ESTIMACION!M12 -> 27.137575 | N12: %
I14: TIPO INTERES ANUAL : | M14: =+'PLAN FINANCIERO'!M14:N14 -> 0.02
I15: COSTE DE OPORTUNIDAD ANUAL : | M15: =+'PLAN FINANCIERO'!M15:N15 -> 0.08
I16: DURACIÓN (MESES):
A18: 1. PREVISIÓN DE CARGA DE TRABAJO (Histograma de recursos)
A42: 2. PREVISIÓN DE LA EVOLUCIÓN DE LOS DATOS ECONÓMICO-FINANCIEROS

Sheet CIERRE
A1: HOJA DE CIERRE ECONÓMICO DEL PROYECTO
A3: DATOS DEL PROYECTO
A5: TITULO: | C5: =IF(ESTIMACION!C5="","N/A",ESTIMACION!C5) -> DESARROLLO DE UN PORTAL WEB | I5: REFERENCIA: | K5: =IF(ESTIMACION!L5="","N/A",ESTIMACION!L5) -> DES-01-2022
A6: CLIENTE: | C6: =IF(ESTIMACION!C6="","N/A",ESTIMACION!C6) -> MEDIOLADO | I6: RESPONSABLE: | K6: =IF(ESTIMACION!L6="","N/A",ESTIMACION!L6) -> PABLO Y CAMILO
K8: PREVISTO | L8: REAL
A9: FECHA INFORME : | D9: 44699 | I9: PRECIO VENTA (SIN IVA): | K9: =+ESTIMACION!M10 -> 97148.99 | L9: =H82 -> 97148.99 | M9: Euros
I10: COSTE: | K10: =+ESTIMACION!N81 -> 76412.492 | L10: =SUM(H88:H92) -> 81360.694 | M10: Euros
I11: ESFUERZO: | K11: =+ESTIMACION!M11 -> 3212 | L11: =H30 -> 3312 | M11: Horas
I12: MARGEN BENEFICIOS: | K12: =+ESTIMACION!M12 -> 27.137575 | L12: =100*(L9-L10)/L10 -> 19.405311 | M12: %
I13: FECHA INICIO: | K13: =IF(ESTIMACION!C8="","N/A",ESTIMACION!C8) -> 44562 | L13: 44562 | M13: mes/año
I14: FECHA FIN: | K14: =IF(ESTIMACION!L8="","N/A",ESTIMACION!L8) -> 44925 | L14: 44925 | M14: mes/año
A16: 1. ESTIMACIÓN DE COSTES Y GASTOS
B18: 1.A | C18: PERSONAL
F19: TOTAL PREVISTO | H19: TOTAL FINAL | K19: DESVIACIÓN
C20: PERSONAL | F20: HORAS TR. | G20: COSTE | H20: HORAS TR. | I20: COSTE | J20: % | K20: HORAS TR. | L20: COSTE | M20: %
C21: =+ESTIMACION!C22 -> Analista | F21: =+ESTIMACION!G22 -> 710 | G21: =+ESTIMACION!N22 -> 16519.602 | H21: 730 | I21: =+H21*ESTIMACION!M22 -> 16984.943 | J21: =+IF(F21=0,"N/A",H21/F21) -> 1.028169 | K21: =+H21-F21 -> 20 | L21: =+I21-G21 -> 465.34091 | M21: =IF(F21=0,"N/A",J21-1) -> 0.028169014
C22: =+ESTIMACION!C23 -> Diseñador Gráfico Aplicativos | F22: =+ESTIMACION!G23 -> 100 | G22: =+ESTIMACION!N23 -> 1551.1364 | H22: 20 | I22: =+H22*ESTIMACION!M23 -> 310.22727 | J22: =+IF(F22=0,"N/A",H22/F22) -> 0.2 | K22: =+H22-F22 -> -80 | L22: =+I22-G22 -> -1240.9091 | M22: =IF(F22=0,"N/A",J22-1) -> -0.8
C23: =+ESTIMACION!C24 -> Jefe de Proyecto | F23: =+ESTIMACION!G24 -> 250 | G23: =+ESTIMACION!N24 -> 7755.6818 | H23: 260 | I23: =+H23*ESTIMACION!M24 -> 8065.9091 | J23: =+IF(F23=0,"N/A",H23/F23) -> 1.04 | K23: =+H23-F23 -> 10 | L23: =+I23-G23 -> 310.22727 | M23: =IF(F23=0,"N/A",J23-1) -> 0.04
C24: =+ESTIMACION!C25 -> Programador | F24: =+ESTIMACION!G25 -> 1720 | G24: =+ESTIMACION!N25 -> 30014.489 | H24: 1870 | I24: =+H24*ESTIMACION!M25 -> 32632.031 | J24: =+IF(F24=0,"N/A",H24/F24) -> 1.0872093 | K24: =+H24-F24 -> 150 | L24: =+I24-G24 -> 2617.5426 | M24: =IF(F24=0,"N/A",J24-1) -> 0.087209302
C25: =+ESTIMACION!C26 -> Supervisor calidad aplicativos | F25: =+ESTIMACION!G26 -> 232 | G25: =+ESTIMACION!N26 -> 6297.6136 | H25: 232 | I25: =+H25*ESTIMACION!M26 -> 6297.6136 | J25: =+IF(F25=0,"N/A",H25/F25) -> 1 | K25: =+H25-F25 -> 0 | L25: =+I25-G25 -> 0 | M25: =IF(F25=0,"N/A",J25-1) -> 0
C26: =+ESTIMACION!C27 -> Técnico de bases de datos | F26: =+ESTIMACION!G27 -> 100 | G26: =+ESTIMACION!N27 -> 2481.8182 | H26: 100 | I26: =+H26*ESTIMACION!M27 -> 2481.8182 | J26: =+IF(F26=0,"N/A",H26/F26) -> 1 | K26: =+H26-F26 -> 0 | L26: =+I26-G26 -> 0 | M26: =IF(F26=0,"N/A",J26-1) -> 0
C27: =+ESTIMACION!C28 -> Técnico de sistemas | F27: =+ESTIMACION!G28 -> 100 | G27: =+ESTIMACION!N28 -> 2481.8182 | H27: 100 | I27: =+H27*ESTIMACION!M28 -> 2481.8182 | J27: =+IF(F27=0,"N/A",H27/F27) -> 1 | K27: =+H27-F27 -> 0 | L27: =+I27-G27 -> 0 | M27: =IF(F27=0,"N/A",J27-1) -> 0
C28: =+ESTIMACION!C29 -> [Insertar más líneas aquí] | F28: =+ESTIMACION!G29 -> 0 | G28: =+ESTIMACION!N29 -> 0 | I28: =+H28*ESTIMACION!J29 -> 0 | J28: =+IF(F28=0,"N/A",H28/F28) -> N/A | K28: =+H28-F28 -> 0 | L28: =+I28-G28 -> 0 | M28: =IF(F28=0,"N/A",J28-1) -> N/A
C30: SUBTOTAL | F30: =SUM(F21:F28) -> 3212 | G30: =SUM(G21:G28) -> 67102.159 | H30: =SUM(H21:H28) -> 3312 | I30: =SUM(I21:I28) -> 69254.361 | J30: =+IF(F30=0,"N/A",H30/F30) -> 1.0311333 | K30: =SUM(K21:K28) -> 100 | L30: =SUM(L21:L28) -> 2152.2017 | M30: =IF(F30=0,"N/A",J30-1) -> 0.03113325
B32: 1.B | C32: SUBCONTRATACIONES
F33: TOTAL PREVISTO | H33: TOTAL FINAL | K33: DESVIACIÓN
C34: EMPRESA | F34: COSTE | H34: COSTE | J34: % | K34: COSTE | M34: %
C35: =+ESTIMACION!C37 -> 3D Designs S.L | F35: =+ESTIMACION!N37 -> 0 | H35: 2150 | J35: =+IF(F35=0,"N/A",H35/F35) -> N/A | K35: =+H35-F35 -> 2150 | M35: =IF(F35=0,"N/A",J35-1) -> N/A
C36: =+ESTIMACION!C38 -> Telefónica | F36: =+ESTIMACION!N38 -> 0 | H36: =49 + 29 -> 78 | J36: =+IF(F36=0,"N/A",H36/F36) -> N/A | K36: =+H36-F36 -> 78 | M36: =IF(F36=0,"N/A",J36-1) -> N/A
C37: =+ESTIMACION!C39 -> 0 | F37: =+ESTIMACION!N39 -> 0 | J37: =+IF(F37=0,"N/A",H37/F37) -> N/A | K37: =+H37-F37 -> 0 | M37: =IF(F37=0,"N/A",J37-1) -> N/A
C38: =+ESTIMACION!C40 -> [Insertar más líneas aquí] | F38: =+ESTIMACION!N40 -> 0 | J38: =+IF(F38=0,"N/A",H38/F38) -> N/A | K38: =+H38-F38 -> 0 | M38: =IF(F38=0,"N/A",J38-1) -> N/A
C40: SUBTOTAL | F40: =SUM(F35:F38) -> 0 | H40: =SUM(H35:H38) -> 2228 | J40: =+IF(F40=0,"N/A",H40/F40) -> N/A | K40: =SUM(K35:K38) -> 2228 | M40: =IF(F40=0,"N/A",J40-1) -> N/A
B43: 1.C | C43: EQUIPAMIENTO
F44: TOTAL PREVISTO | H44: TOTAL FINAL | K44: DESVIACIÓN
C45: EQUIPO | F45: COSTE | H45: COSTE | J45: % | K45: COSTE | M45: %
C46: =+ESTIMACION!C48 -> HW-SERV | F46: =+ESTIMACION!N48 -> 4896 | H46: 4700 | J46: =+IF(F46=0,"N/A",H46/F46) -> 0.95996732 | K46: =+H46-F46 -> -196 | M46: =IF(F46=0,"N/A",J46-1) -> -0.04003268
C47: =+ESTIMACION!C49 -> SW-SERV | F47: =+ESTIMACION!N49 -> 255 | H47: 399 | J47: =+IF(F47=0,"N/A",H47/F47) -> 1.5647059 | K47: =+H47-F47 -> 144 | M47: =IF(F47=0,"N/A",J47-1) -> 0.56470588
C48: =+ESTIMACION!C50 -> 0 | F48: =+ESTIMACION!N50 -> 0 | J48: =+IF(F48=0,"N/A",H48/F48) -> N/A | K48: =+H48-F48 -> 0 | M48: =IF(F48=0,"N/A",J48-1) -> N/A
C49: =+ESTIMACION!C51 -> [Insertar más líneas aquí] | F49: =+ESTIMACION!N51 -> 0 | J49: =+IF(F49=0,"N/A",H49/F49) -> N/A | K49: =+H49-F49 -> 0 | M49: =IF(F49=0,"N/A",J49-1) -> N/A
C51: SUBTOTAL | F51: =SUM(F46:F49) -> 5151 | H51: =SUM(H46:H49) -> 5099 | J51: =+IF(F51=0,"N/A",H51/F51) -> 0.98990487 | K51: =SUM(K46:K49) -> -52 | M51: =IF(F51=0,"N/A",J51-1) -> -0.010095127
...
